INFO:     Will watch for changes in these directories: ['/workspaces/CICDLAB2']
INFO:     Uvicorn running on http://0.0.0.0:8000 (Press CTRL+C to quit)
INFO:     Started reloader process [20740] using StatReload
Process SpawnProcess-1:
Traceback (most recent call last):
  File "/usr/local/python/3.12.1/lib/python3.12/multiprocessing/process.py", line 314, in _bootstrap
    self.run()
  File "/usr/local/python/3.12.1/lib/python3.12/multiprocessing/process.py", line 108, in run
    self._target(*self._args, **self._kwargs)
  File "/home/codespace/.local/lib/python3.12/site-packages/uvicorn/_subprocess.py", line 80, in subprocess_started
    target(sockets=sockets)
  File "/home/codespace/.local/lib/python3.12/site-packages/uvicorn/server.py", line 67, in run
    return asyncio_run(self.serve(sockets=sockets), loop_factory=self.config.get_loop_factory())
           ^^^^^^^^^^^^^^^^^^^^^^^^^^^^^^^^^^^^^^^^^^^^^^^^^^^^^^^^^^^^^^^^^^^^^^^^^^^^^^^^^^^^^
  File "/usr/local/python/3.12.1/lib/python3.12/asyncio/runners.py", line 194, in run
    return runner.run(main)
           ^^^^^^^^^^^^^^^^
  File "/usr/local/python/3.12.1/lib/python3.12/asyncio/runners.py", line 118, in run
    return self._loop.run_until_complete(task)
           ^^^^^^^^^^^^^^^^^^^^^^^^^^^^^^^^^^^
  File "/usr/local/python/3.12.1/lib/python3.12/asyncio/base_events.py", line 684, in run_until_complete
    return future.result()
           ^^^^^^^^^^^^^^^
  File "/home/codespace/.local/lib/python3.12/site-packages/uvicorn/server.py", line 71, in serve
    await self._serve(sockets)
  File "/home/codespace/.local/lib/python3.12/site-packages/uvicorn/server.py", line 78, in _serve
    config.load()
  File "/home/codespace/.local/lib/python3.12/site-packages/uvicorn/config.py", line 438, in load
    self.loaded_app = import_from_string(self.app)
                      ^^^^^^^^^^^^^^^^^^^^^^^^^^^^
  File "/home/codespace/.local/lib/python3.12/site-packages/uvicorn/importer.py", line 22, in import_from_string
    raise exc from None
  File "/home/codespace/.local/lib/python3.12/site-packages/uvicorn/importer.py", line 19, in import_from_string
    module = importlib.import_module(module_str)
             ^^^^^^^^^^^^^^^^^^^^^^^^^^^^^^^^^^^
  File "/usr/local/python/3.12.1/lib/python3.12/importlib/__init__.py", line 90, in import_module
    return _bootstrap._gcd_import(name[level:], package, level)
           ^^^^^^^^^^^^^^^^^^^^^^^^^^^^^^^^^^^^^^^^^^^^^^^^^^^^
  File "<frozen importlib._bootstrap>", line 1387, in _gcd_import
  File "<frozen importlib._bootstrap>", line 1360, in _find_and_load
  File "<frozen importlib._bootstrap>", line 1331, in _find_and_load_unlocked
  File "<frozen importlib._bootstrap>", line 935, in _load_unlocked
  File "<frozen importlib._bootstrap_external>", line 994, in exec_module
  File "<frozen importlib._bootstrap>", line 488, in _call_with_frames_removed
  File "/workspaces/CICDLAB2/app/main.py", line 5, in <module>
    from .database import engine, SessionLocal
ModuleNotFoundError: No module named 'app.database'
WARNING:  StatReload detected changes in 'app/main.py'. Reloading...
INFO:     Started server process [30530]
INFO:     Waiting for application startup.
INFO:     Application startup complete.
ERROR:    Traceback (most recent call last):
  File "/usr/local/python/3.12.1/lib/python3.12/asyncio/runners.py", line 194, in run
    return runner.run(main)
           ^^^^^^^^^^^^^^^^
  File "/usr/local/python/3.12.1/lib/python3.12/asyncio/runners.py", line 118, in run
    return self._loop.run_until_complete(task)
           ^^^^^^^^^^^^^^^^^^^^^^^^^^^^^^^^^^^
  File "/usr/local/python/3.12.1/lib/python3.12/asyncio/base_events.py", line 684, in run_until_complete
    return future.result()
           ^^^^^^^^^^^^^^^
  File "/home/codespace/.local/lib/python3.12/site-packages/uvicorn/server.py", line 71, in serve
    await self._serve(sockets)
  File "/home/codespace/.local/lib/python3.12/site-packages/uvicorn/server.py", line 86, in _serve
    await self.startup(sockets=sockets)
  File "/home/codespace/.local/lib/python3.12/site-packages/uvicorn/server.py", line 136, in startup
    server = await loop.create_server(create_protocol, sock=sock, ssl=config.ssl, backlog=config.backlog)
             ^^^^^^^^^^^^^^^^^^^^^^^^^^^^^^^^^^^^^^^^^^^^^^^^^^^^^^^^^^^^^^^^^^^^^^^^^^^^^^^^^^^^^^^^^^^^
  File "/usr/local/python/3.12.1/lib/python3.12/asyncio/base_events.py", line 1581, in create_server
    server._start_serving()
  File "/usr/local/python/3.12.1/lib/python3.12/asyncio/base_events.py", line 315, in _start_serving
    sock.listen(self._backlog)
OSError: [Errno 98] Address already in use

During handling of the above exception, another exception occurred:

Traceback (most recent call last):
  File "/home/codespace/.local/lib/python3.12/site-packages/starlette/routing.py", line 701, in lifespan
    await receive()
  File "/home/codespace/.local/lib/python3.12/site-packages/uvicorn/lifespan/on.py", line 137, in receive
    return await self.receive_queue.get()
           ^^^^^^^^^^^^^^^^^^^^^^^^^^^^^^
  File "/usr/local/python/3.12.1/lib/python3.12/asyncio/queues.py", line 158, in get
    await getter
asyncio.exceptions.CancelledError

Process SpawnProcess-2:
Traceback (most recent call last):
  File "/usr/local/python/3.12.1/lib/python3.12/multiprocessing/process.py", line 314, in _bootstrap
    self.run()
  File "/usr/local/python/3.12.1/lib/python3.12/multiprocessing/process.py", line 108, in run
    self._target(*self._args, **self._kwargs)
  File "/home/codespace/.local/lib/python3.12/site-packages/uvicorn/_subprocess.py", line 80, in subprocess_started
    target(sockets=sockets)
  File "/home/codespace/.local/lib/python3.12/site-packages/uvicorn/server.py", line 67, in run
    return asyncio_run(self.serve(sockets=sockets), loop_factory=self.config.get_loop_factory())
           ^^^^^^^^^^^^^^^^^^^^^^^^^^^^^^^^^^^^^^^^^^^^^^^^^^^^^^^^^^^^^^^^^^^^^^^^^^^^^^^^^^^^^
  File "/usr/local/python/3.12.1/lib/python3.12/asyncio/runners.py", line 194, in run
    return runner.run(main)
           ^^^^^^^^^^^^^^^^
  File "/usr/local/python/3.12.1/lib/python3.12/asyncio/runners.py", line 118, in run
    return self._loop.run_until_complete(task)
           ^^^^^^^^^^^^^^^^^^^^^^^^^^^^^^^^^^^
  File "/usr/local/python/3.12.1/lib/python3.12/asyncio/base_events.py", line 684, in run_until_complete
    return future.result()
           ^^^^^^^^^^^^^^^
  File "/home/codespace/.local/lib/python3.12/site-packages/uvicorn/server.py", line 71, in serve
    await self._serve(sockets)
  File "/home/codespace/.local/lib/python3.12/site-packages/uvicorn/server.py", line 86, in _serve
    await self.startup(sockets=sockets)
  File "/home/codespace/.local/lib/python3.12/site-packages/uvicorn/server.py", line 136, in startup
    server = await loop.create_server(create_protocol, sock=sock, ssl=config.ssl, backlog=config.backlog)
             ^^^^^^^^^^^^^^^^^^^^^^^^^^^^^^^^^^^^^^^^^^^^^^^^^^^^^^^^^^^^^^^^^^^^^^^^^^^^^^^^^^^^^^^^^^^^
  File "/usr/local/python/3.12.1/lib/python3.12/asyncio/base_events.py", line 1581, in create_server
    server._start_serving()
  File "/usr/local/python/3.12.1/lib/python3.12/asyncio/base_events.py", line 315, in _start_serving
    sock.listen(self._backlog)
OSError: [Errno 98] Address already in use
WARNING:  StatReload detected changes in 'app/main.py'. Reloading...
INFO:     Started server process [30580]
INFO:     Waiting for application startup.
INFO:     Application startup complete.
ERROR:    Traceback (most recent call last):
  File "/usr/local/python/3.12.1/lib/python3.12/asyncio/runners.py", line 194, in run
    return runner.run(main)
           ^^^^^^^^^^^^^^^^
  File "/usr/local/python/3.12.1/lib/python3.12/asyncio/runners.py", line 118, in run
    return self._loop.run_until_complete(task)
           ^^^^^^^^^^^^^^^^^^^^^^^^^^^^^^^^^^^
  File "/usr/local/python/3.12.1/lib/python3.12/asyncio/base_events.py", line 684, in run_until_complete
    return future.result()
           ^^^^^^^^^^^^^^^
  File "/home/codespace/.local/lib/python3.12/site-packages/uvicorn/server.py", line 71, in serve
    await self._serve(sockets)
  File "/home/codespace/.local/lib/python3.12/site-packages/uvicorn/server.py", line 86, in _serve
    await self.startup(sockets=sockets)
  File "/home/codespace/.local/lib/python3.12/site-packages/uvicorn/server.py", line 136, in startup
    server = await loop.create_server(create_protocol, sock=sock, ssl=config.ssl, backlog=config.backlog)
             ^^^^^^^^^^^^^^^^^^^^^^^^^^^^^^^^^^^^^^^^^^^^^^^^^^^^^^^^^^^^^^^^^^^^^^^^^^^^^^^^^^^^^^^^^^^^
  File "/usr/local/python/3.12.1/lib/python3.12/asyncio/base_events.py", line 1581, in create_server
    server._start_serving()
  File "/usr/local/python/3.12.1/lib/python3.12/asyncio/base_events.py", line 315, in _start_serving
    sock.listen(self._backlog)
OSError: [Errno 98] Address already in use

During handling of the above exception, another exception occurred:

Traceback (most recent call last):
  File "/home/codespace/.local/lib/python3.12/site-packages/starlette/routing.py", line 701, in lifespan
    await receive()
  File "/home/codespace/.local/lib/python3.12/site-packages/uvicorn/lifespan/on.py", line 137, in receive
    return await self.receive_queue.get()
           ^^^^^^^^^^^^^^^^^^^^^^^^^^^^^^
  File "/usr/local/python/3.12.1/lib/python3.12/asyncio/queues.py", line 158, in get
    await getter
asyncio.exceptions.CancelledError

Process SpawnProcess-3:
Traceback (most recent call last):
  File "/usr/local/python/3.12.1/lib/python3.12/multiprocessing/process.py", line 314, in _bootstrap
    self.run()
  File "/usr/local/python/3.12.1/lib/python3.12/multiprocessing/process.py", line 108, in run
    self._target(*self._args, **self._kwargs)
  File "/home/codespace/.local/lib/python3.12/site-packages/uvicorn/_subprocess.py", line 80, in subprocess_started
    target(sockets=sockets)
  File "/home/codespace/.local/lib/python3.12/site-packages/uvicorn/server.py", line 67, in run
    return asyncio_run(self.serve(sockets=sockets), loop_factory=self.config.get_loop_factory())
           ^^^^^^^^^^^^^^^^^^^^^^^^^^^^^^^^^^^^^^^^^^^^^^^^^^^^^^^^^^^^^^^^^^^^^^^^^^^^^^^^^^^^^
  File "/usr/local/python/3.12.1/lib/python3.12/asyncio/runners.py", line 194, in run
    return runner.run(main)
           ^^^^^^^^^^^^^^^^
  File "/usr/local/python/3.12.1/lib/python3.12/asyncio/runners.py", line 118, in run
    return self._loop.run_until_complete(task)
           ^^^^^^^^^^^^^^^^^^^^^^^^^^^^^^^^^^^
  File "/usr/local/python/3.12.1/lib/python3.12/asyncio/base_events.py", line 684, in run_until_complete
    return future.result()
           ^^^^^^^^^^^^^^^
  File "/home/codespace/.local/lib/python3.12/site-packages/uvicorn/server.py", line 71, in serve
    await self._serve(sockets)
  File "/home/codespace/.local/lib/python3.12/site-packages/uvicorn/server.py", line 86, in _serve
    await self.startup(sockets=sockets)
  File "/home/codespace/.local/lib/python3.12/site-packages/uvicorn/server.py", line 136, in startup
    server = await loop.create_server(create_protocol, sock=sock, ssl=config.ssl, backlog=config.backlog)
             ^^^^^^^^^^^^^^^^^^^^^^^^^^^^^^^^^^^^^^^^^^^^^^^^^^^^^^^^^^^^^^^^^^^^^^^^^^^^^^^^^^^^^^^^^^^^
  File "/usr/local/python/3.12.1/lib/python3.12/asyncio/base_events.py", line 1581, in create_server
    server._start_serving()
  File "/usr/local/python/3.12.1/lib/python3.12/asyncio/base_events.py", line 315, in _start_serving
    sock.listen(self._backlog)
OSError: [Errno 98] Address already in use
WARNING:  StatReload detected changes in 'app/main.py'. Reloading...
Process SpawnProcess-4:
Traceback (most recent call last):
  File "/usr/local/python/3.12.1/lib/python3.12/multiprocessing/process.py", line 314, in _bootstrap
    self.run()
  File "/usr/local/python/3.12.1/lib/python3.12/multiprocessing/process.py", line 108, in run
    self._target(*self._args, **self._kwargs)
  File "/home/codespace/.local/lib/python3.12/site-packages/uvicorn/_subprocess.py", line 80, in subprocess_started
    target(sockets=sockets)
  File "/home/codespace/.local/lib/python3.12/site-packages/uvicorn/server.py", line 67, in run
    return asyncio_run(self.serve(sockets=sockets), loop_factory=self.config.get_loop_factory())
           ^^^^^^^^^^^^^^^^^^^^^^^^^^^^^^^^^^^^^^^^^^^^^^^^^^^^^^^^^^^^^^^^^^^^^^^^^^^^^^^^^^^^^
  File "/usr/local/python/3.12.1/lib/python3.12/asyncio/runners.py", line 194, in run
    return runner.run(main)
           ^^^^^^^^^^^^^^^^
  File "/usr/local/python/3.12.1/lib/python3.12/asyncio/runners.py", line 118, in run
    return self._loop.run_until_complete(task)
           ^^^^^^^^^^^^^^^^^^^^^^^^^^^^^^^^^^^
  File "/usr/local/python/3.12.1/lib/python3.12/asyncio/base_events.py", line 684, in run_until_complete
    return future.result()
           ^^^^^^^^^^^^^^^
  File "/home/codespace/.local/lib/python3.12/site-packages/uvicorn/server.py", line 71, in serve
    await self._serve(sockets)
  File "/home/codespace/.local/lib/python3.12/site-packages/uvicorn/server.py", line 78, in _serve
    config.load()
  File "/home/codespace/.local/lib/python3.12/site-packages/uvicorn/config.py", line 438, in load
    self.loaded_app = import_from_string(self.app)
                      ^^^^^^^^^^^^^^^^^^^^^^^^^^^^
  File "/home/codespace/.local/lib/python3.12/site-packages/uvicorn/importer.py", line 19, in import_from_string
    module = importlib.import_module(module_str)
             ^^^^^^^^^^^^^^^^^^^^^^^^^^^^^^^^^^^
  File "/usr/local/python/3.12.1/lib/python3.12/importlib/__init__.py", line 90, in import_module
    return _bootstrap._gcd_import(name[level:], package, level)
           ^^^^^^^^^^^^^^^^^^^^^^^^^^^^^^^^^^^^^^^^^^^^^^^^^^^^
  File "<frozen importlib._bootstrap>", line 1387, in _gcd_import
  File "<frozen importlib._bootstrap>", line 1360, in _find_and_load
  File "<frozen importlib._bootstrap>", line 1331, in _find_and_load_unlocked
  File "<frozen importlib._bootstrap>", line 935, in _load_unlocked
  File "<frozen importlib._bootstrap_external>", line 990, in exec_module
  File "<frozen importlib._bootstrap_external>", line 1128, in get_code
  File "<frozen importlib._bootstrap_external>", line 1058, in source_to_code
  File "<frozen importlib._bootstrap>", line 488, in _call_with_frames_removed
  File "/workspaces/CICDLAB2/app/main.py", line 41
    @app.get
SyntaxError: invalid syntax
WARNING:  StatReload detected changes in 'app/main.py'. Reloading...
Process SpawnProcess-5:
Traceback (most recent call last):
  File "/usr/local/python/3.12.1/lib/python3.12/multiprocessing/process.py", line 314, in _bootstrap
    self.run()
  File "/usr/local/python/3.12.1/lib/python3.12/multiprocessing/process.py", line 108, in run
    self._target(*self._args, **self._kwargs)
  File "/home/codespace/.local/lib/python3.12/site-packages/uvicorn/_subprocess.py", line 80, in subprocess_started
    target(sockets=sockets)
  File "/home/codespace/.local/lib/python3.12/site-packages/uvicorn/server.py", line 67, in run
    return asyncio_run(self.serve(sockets=sockets), loop_factory=self.config.get_loop_factory())
           ^^^^^^^^^^^^^^^^^^^^^^^^^^^^^^^^^^^^^^^^^^^^^^^^^^^^^^^^^^^^^^^^^^^^^^^^^^^^^^^^^^^^^
  File "/usr/local/python/3.12.1/lib/python3.12/asyncio/runners.py", line 194, in run
    return runner.run(main)
           ^^^^^^^^^^^^^^^^
  File "/usr/local/python/3.12.1/lib/python3.12/asyncio/runners.py", line 118, in run
    return self._loop.run_until_complete(task)
           ^^^^^^^^^^^^^^^^^^^^^^^^^^^^^^^^^^^
  File "/usr/local/python/3.12.1/lib/python3.12/asyncio/base_events.py", line 684, in run_until_complete
    return future.result()
           ^^^^^^^^^^^^^^^
  File "/home/codespace/.local/lib/python3.12/site-packages/uvicorn/server.py", line 71, in serve
    await self._serve(sockets)
  File "/home/codespace/.local/lib/python3.12/site-packages/uvicorn/server.py", line 78, in _serve
    config.load()
  File "/home/codespace/.local/lib/python3.12/site-packages/uvicorn/config.py", line 438, in load
    self.loaded_app = import_from_string(self.app)
                      ^^^^^^^^^^^^^^^^^^^^^^^^^^^^
  File "/home/codespace/.local/lib/python3.12/site-packages/uvicorn/importer.py", line 19, in import_from_string
    module = importlib.import_module(module_str)
             ^^^^^^^^^^^^^^^^^^^^^^^^^^^^^^^^^^^
  File "/usr/local/python/3.12.1/lib/python3.12/importlib/__init__.py", line 90, in import_module
    return _bootstrap._gcd_import(name[level:], package, level)
           ^^^^^^^^^^^^^^^^^^^^^^^^^^^^^^^^^^^^^^^^^^^^^^^^^^^^
  File "<frozen importlib._bootstrap>", line 1387, in _gcd_import
  File "<frozen importlib._bootstrap>", line 1360, in _find_and_load
  File "<frozen importlib._bootstrap>", line 1331, in _find_and_load_unlocked
  File "<frozen importlib._bootstrap>", line 935, in _load_unlocked
  File "<frozen importlib._bootstrap_external>", line 990, in exec_module
  File "<frozen importlib._bootstrap_external>", line 1128, in get_code
  File "<frozen importlib._bootstrap_external>", line 1058, in source_to_code
  File "<frozen importlib._bootstrap>", line 488, in _call_with_frames_removed
  File "/workspaces/CICDLAB2/app/main.py", line 41
    @app.get()
SyntaxError: invalid syntax
WARNING:  StatReload detected changes in 'app/main.py'. Reloading...
Process SpawnProcess-6:
Traceback (most recent call last):
  File "/usr/local/python/3.12.1/lib/python3.12/multiprocessing/process.py", line 314, in _bootstrap
    self.run()
  File "/usr/local/python/3.12.1/lib/python3.12/multiprocessing/process.py", line 108, in run
    self._target(*self._args, **self._kwargs)
  File "/home/codespace/.local/lib/python3.12/site-packages/uvicorn/_subprocess.py", line 80, in subprocess_started
    target(sockets=sockets)
  File "/home/codespace/.local/lib/python3.12/site-packages/uvicorn/server.py", line 67, in run
    return asyncio_run(self.serve(sockets=sockets), loop_factory=self.config.get_loop_factory())
           ^^^^^^^^^^^^^^^^^^^^^^^^^^^^^^^^^^^^^^^^^^^^^^^^^^^^^^^^^^^^^^^^^^^^^^^^^^^^^^^^^^^^^
  File "/usr/local/python/3.12.1/lib/python3.12/asyncio/runners.py", line 194, in run
    return runner.run(main)
           ^^^^^^^^^^^^^^^^
  File "/usr/local/python/3.12.1/lib/python3.12/asyncio/runners.py", line 118, in run
    return self._loop.run_until_complete(task)
           ^^^^^^^^^^^^^^^^^^^^^^^^^^^^^^^^^^^
  File "/usr/local/python/3.12.1/lib/python3.12/asyncio/base_events.py", line 684, in run_until_complete
    return future.result()
           ^^^^^^^^^^^^^^^
  File "/home/codespace/.local/lib/python3.12/site-packages/uvicorn/server.py", line 71, in serve
    await self._serve(sockets)
  File "/home/codespace/.local/lib/python3.12/site-packages/uvicorn/server.py", line 78, in _serve
    config.load()
  File "/home/codespace/.local/lib/python3.12/site-packages/uvicorn/config.py", line 438, in load
    self.loaded_app = import_from_string(self.app)
                      ^^^^^^^^^^^^^^^^^^^^^^^^^^^^
  File "/home/codespace/.local/lib/python3.12/site-packages/uvicorn/importer.py", line 19, in import_from_string
    module = importlib.import_module(module_str)
             ^^^^^^^^^^^^^^^^^^^^^^^^^^^^^^^^^^^
  File "/usr/local/python/3.12.1/lib/python3.12/importlib/__init__.py", line 90, in import_module
    return _bootstrap._gcd_import(name[level:], package, level)
           ^^^^^^^^^^^^^^^^^^^^^^^^^^^^^^^^^^^^^^^^^^^^^^^^^^^^
  File "<frozen importlib._bootstrap>", line 1387, in _gcd_import
  File "<frozen importlib._bootstrap>", line 1360, in _find_and_load
  File "<frozen importlib._bootstrap>", line 1331, in _find_and_load_unlocked
  File "<frozen importlib._bootstrap>", line 935, in _load_unlocked
  File "<frozen importlib._bootstrap_external>", line 990, in exec_module
  File "<frozen importlib._bootstrap_external>", line 1128, in get_code
  File "<frozen importlib._bootstrap_external>", line 1058, in source_to_code
  File "<frozen importlib._bootstrap>", line 488, in _call_with_frames_removed
  File "/workspaces/CICDLAB2/app/main.py", line 41
    @app.get("")
SyntaxError: invalid syntax
WARNING:  StatReload detected changes in 'app/main.py'. Reloading...
Process SpawnProcess-7:
Traceback (most recent call last):
  File "/usr/local/python/3.12.1/lib/python3.12/multiprocessing/process.py", line 314, in _bootstrap
    self.run()
  File "/usr/local/python/3.12.1/lib/python3.12/multiprocessing/process.py", line 108, in run
    self._target(*self._args, **self._kwargs)
  File "/home/codespace/.local/lib/python3.12/site-packages/uvicorn/_subprocess.py", line 80, in subprocess_started
    target(sockets=sockets)
  File "/home/codespace/.local/lib/python3.12/site-packages/uvicorn/server.py", line 67, in run
    return asyncio_run(self.serve(sockets=sockets), loop_factory=self.config.get_loop_factory())
           ^^^^^^^^^^^^^^^^^^^^^^^^^^^^^^^^^^^^^^^^^^^^^^^^^^^^^^^^^^^^^^^^^^^^^^^^^^^^^^^^^^^^^
  File "/usr/local/python/3.12.1/lib/python3.12/asyncio/runners.py", line 194, in run
    return runner.run(main)
           ^^^^^^^^^^^^^^^^
  File "/usr/local/python/3.12.1/lib/python3.12/asyncio/runners.py", line 118, in run
    return self._loop.run_until_complete(task)
           ^^^^^^^^^^^^^^^^^^^^^^^^^^^^^^^^^^^
  File "/usr/local/python/3.12.1/lib/python3.12/asyncio/base_events.py", line 684, in run_until_complete
    return future.result()
           ^^^^^^^^^^^^^^^
  File "/home/codespace/.local/lib/python3.12/site-packages/uvicorn/server.py", line 71, in serve
    await self._serve(sockets)
  File "/home/codespace/.local/lib/python3.12/site-packages/uvicorn/server.py", line 78, in _serve
    config.load()
  File "/home/codespace/.local/lib/python3.12/site-packages/uvicorn/config.py", line 438, in load
    self.loaded_app = import_from_string(self.app)
                      ^^^^^^^^^^^^^^^^^^^^^^^^^^^^
  File "/home/codespace/.local/lib/python3.12/site-packages/uvicorn/importer.py", line 19, in import_from_string
    module = importlib.import_module(module_str)
             ^^^^^^^^^^^^^^^^^^^^^^^^^^^^^^^^^^^
  File "/usr/local/python/3.12.1/lib/python3.12/importlib/__init__.py", line 90, in import_module
    return _bootstrap._gcd_import(name[level:], package, level)
           ^^^^^^^^^^^^^^^^^^^^^^^^^^^^^^^^^^^^^^^^^^^^^^^^^^^^
  File "<frozen importlib._bootstrap>", line 1387, in _gcd_import
  File "<frozen importlib._bootstrap>", line 1360, in _find_and_load
  File "<frozen importlib._bootstrap>", line 1331, in _find_and_load_unlocked
  File "<frozen importlib._bootstrap>", line 935, in _load_unlocked
  File "<frozen importlib._bootstrap_external>", line 990, in exec_module
  File "<frozen importlib._bootstrap_external>", line 1128, in get_code
  File "<frozen importlib._bootstrap_external>", line 1058, in source_to_code
  File "<frozen importlib._bootstrap>", line 488, in _call_with_frames_removed
  File "/workspaces/CICDLAB2/app/main.py", line 41
    @app.get("/api/heal")
SyntaxError: invalid syntax
WARNING:  StatReload detected changes in 'app/main.py'. Reloading...
Process SpawnProcess-8:
Traceback (most recent call last):
  File "/usr/local/python/3.12.1/lib/python3.12/multiprocessing/process.py", line 314, in _bootstrap
    self.run()
  File "/usr/local/python/3.12.1/lib/python3.12/multiprocessing/process.py", line 108, in run
    self._target(*self._args, **self._kwargs)
  File "/home/codespace/.local/lib/python3.12/site-packages/uvicorn/_subprocess.py", line 80, in subprocess_started
    target(sockets=sockets)
  File "/home/codespace/.local/lib/python3.12/site-packages/uvicorn/server.py", line 67, in run
    return asyncio_run(self.serve(sockets=sockets), loop_factory=self.config.get_loop_factory())
           ^^^^^^^^^^^^^^^^^^^^^^^^^^^^^^^^^^^^^^^^^^^^^^^^^^^^^^^^^^^^^^^^^^^^^^^^^^^^^^^^^^^^^
  File "/usr/local/python/3.12.1/lib/python3.12/asyncio/runners.py", line 194, in run
    return runner.run(main)
           ^^^^^^^^^^^^^^^^
  File "/usr/local/python/3.12.1/lib/python3.12/asyncio/runners.py", line 118, in run
    return self._loop.run_until_complete(task)
           ^^^^^^^^^^^^^^^^^^^^^^^^^^^^^^^^^^^
  File "/usr/local/python/3.12.1/lib/python3.12/asyncio/base_events.py", line 684, in run_until_complete
    return future.result()
           ^^^^^^^^^^^^^^^
  File "/home/codespace/.local/lib/python3.12/site-packages/uvicorn/server.py", line 71, in serve
    await self._serve(sockets)
  File "/home/codespace/.local/lib/python3.12/site-packages/uvicorn/server.py", line 78, in _serve
    config.load()
  File "/home/codespace/.local/lib/python3.12/site-packages/uvicorn/config.py", line 438, in load
    self.loaded_app = import_from_string(self.app)
                      ^^^^^^^^^^^^^^^^^^^^^^^^^^^^
  File "/home/codespace/.local/lib/python3.12/site-packages/uvicorn/importer.py", line 19, in import_from_string
    module = importlib.import_module(module_str)
             ^^^^^^^^^^^^^^^^^^^^^^^^^^^^^^^^^^^
  File "/usr/local/python/3.12.1/lib/python3.12/importlib/__init__.py", line 90, in import_module
    return _bootstrap._gcd_import(name[level:], package, level)
           ^^^^^^^^^^^^^^^^^^^^^^^^^^^^^^^^^^^^^^^^^^^^^^^^^^^^
  File "<frozen importlib._bootstrap>", line 1387, in _gcd_import
  File "<frozen importlib._bootstrap>", line 1360, in _find_and_load
  File "<frozen importlib._bootstrap>", line 1331, in _find_and_load_unlocked
  File "<frozen importlib._bootstrap>", line 935, in _load_unlocked
  File "<frozen importlib._bootstrap_external>", line 990, in exec_module
  File "<frozen importlib._bootstrap_external>", line 1128, in get_code
  File "<frozen importlib._bootstrap_external>", line 1058, in source_to_code
  File "<frozen importlib._bootstrap>", line 488, in _call_with_frames_removed
  File "/workspaces/CICDLAB2/app/main.py", line 41
    @app.get("/api/health   ")
SyntaxError: invalid syntax
WARNING:  StatReload detected changes in 'app/main.py'. Reloading...
Process SpawnProcess-9:
Traceback (most recent call last):
  File "/usr/local/python/3.12.1/lib/python3.12/multiprocessing/process.py", line 314, in _bootstrap
    self.run()
  File "/usr/local/python/3.12.1/lib/python3.12/multiprocessing/process.py", line 108, in run
    self._target(*self._args, **self._kwargs)
  File "/home/codespace/.local/lib/python3.12/site-packages/uvicorn/_subprocess.py", line 80, in subprocess_started
    target(sockets=sockets)
  File "/home/codespace/.local/lib/python3.12/site-packages/uvicorn/server.py", line 67, in run
    return asyncio_run(self.serve(sockets=sockets), loop_factory=self.config.get_loop_factory())
           ^^^^^^^^^^^^^^^^^^^^^^^^^^^^^^^^^^^^^^^^^^^^^^^^^^^^^^^^^^^^^^^^^^^^^^^^^^^^^^^^^^^^^
  File "/usr/local/python/3.12.1/lib/python3.12/asyncio/runners.py", line 194, in run
    return runner.run(main)
           ^^^^^^^^^^^^^^^^
  File "/usr/local/python/3.12.1/lib/python3.12/asyncio/runners.py", line 118, in run
    return self._loop.run_until_complete(task)
           ^^^^^^^^^^^^^^^^^^^^^^^^^^^^^^^^^^^
  File "/usr/local/python/3.12.1/lib/python3.12/asyncio/base_events.py", line 684, in run_until_complete
    return future.result()
           ^^^^^^^^^^^^^^^
  File "/home/codespace/.local/lib/python3.12/site-packages/uvicorn/server.py", line 71, in serve
    await self._serve(sockets)
  File "/home/codespace/.local/lib/python3.12/site-packages/uvicorn/server.py", line 78, in _serve
    config.load()
  File "/home/codespace/.local/lib/python3.12/site-packages/uvicorn/config.py", line 438, in load
    self.loaded_app = import_from_string(self.app)
                      ^^^^^^^^^^^^^^^^^^^^^^^^^^^^
  File "/home/codespace/.local/lib/python3.12/site-packages/uvicorn/importer.py", line 19, in import_from_string
    module = importlib.import_module(module_str)
             ^^^^^^^^^^^^^^^^^^^^^^^^^^^^^^^^^^^
  File "/usr/local/python/3.12.1/lib/python3.12/importlib/__init__.py", line 90, in import_module
    return _bootstrap._gcd_import(name[level:], package, level)
           ^^^^^^^^^^^^^^^^^^^^^^^^^^^^^^^^^^^^^^^^^^^^^^^^^^^^
  File "<frozen importlib._bootstrap>", line 1387, in _gcd_import
  File "<frozen importlib._bootstrap>", line 1360, in _find_and_load
  File "<frozen importlib._bootstrap>", line 1331, in _find_and_load_unlocked
  File "<frozen importlib._bootstrap>", line 935, in _load_unlocked
  File "<frozen importlib._bootstrap_external>", line 990, in exec_module
  File "<frozen importlib._bootstrap_external>", line 1128, in get_code
  File "<frozen importlib._bootstrap_external>", line 1058, in source_to_code
  File "<frozen importlib._bootstrap>", line 488, in _call_with_frames_removed
  File "/workspaces/CICDLAB2/app/main.py", line 41
    @app.get("/api/health")
SyntaxError: invalid syntax
WARNING:  StatReload detected changes in 'app/main.py'. Reloading...
Process SpawnProcess-10:
Traceback (most recent call last):
  File "/usr/local/python/3.12.1/lib/python3.12/multiprocessing/process.py", line 314, in _bootstrap
    self.run()
  File "/usr/local/python/3.12.1/lib/python3.12/multiprocessing/process.py", line 108, in run
    self._target(*self._args, **self._kwargs)
  File "/home/codespace/.local/lib/python3.12/site-packages/uvicorn/_subprocess.py", line 80, in subprocess_started
    target(sockets=sockets)
  File "/home/codespace/.local/lib/python3.12/site-packages/uvicorn/server.py", line 67, in run
    return asyncio_run(self.serve(sockets=sockets), loop_factory=self.config.get_loop_factory())
           ^^^^^^^^^^^^^^^^^^^^^^^^^^^^^^^^^^^^^^^^^^^^^^^^^^^^^^^^^^^^^^^^^^^^^^^^^^^^^^^^^^^^^
  File "/usr/local/python/3.12.1/lib/python3.12/asyncio/runners.py", line 194, in run
    return runner.run(main)
           ^^^^^^^^^^^^^^^^
  File "/usr/local/python/3.12.1/lib/python3.12/asyncio/runners.py", line 118, in run
    return self._loop.run_until_complete(task)
           ^^^^^^^^^^^^^^^^^^^^^^^^^^^^^^^^^^^
  File "/usr/local/python/3.12.1/lib/python3.12/asyncio/base_events.py", line 684, in run_until_complete
    return future.result()
           ^^^^^^^^^^^^^^^
  File "/home/codespace/.local/lib/python3.12/site-packages/uvicorn/server.py", line 71, in serve
    await self._serve(sockets)
  File "/home/codespace/.local/lib/python3.12/site-packages/uvicorn/server.py", line 78, in _serve
    config.load()
  File "/home/codespace/.local/lib/python3.12/site-packages/uvicorn/config.py", line 438, in load
    self.loaded_app = import_from_string(self.app)
                      ^^^^^^^^^^^^^^^^^^^^^^^^^^^^
  File "/home/codespace/.local/lib/python3.12/site-packages/uvicorn/importer.py", line 19, in import_from_string
    module = importlib.import_module(module_str)
             ^^^^^^^^^^^^^^^^^^^^^^^^^^^^^^^^^^^
  File "/usr/local/python/3.12.1/lib/python3.12/importlib/__init__.py", line 90, in import_module
    return _bootstrap._gcd_import(name[level:], package, level)
           ^^^^^^^^^^^^^^^^^^^^^^^^^^^^^^^^^^^^^^^^^^^^^^^^^^^^
  File "<frozen importlib._bootstrap>", line 1387, in _gcd_import
  File "<frozen importlib._bootstrap>", line 1360, in _find_and_load
  File "<frozen importlib._bootstrap>", line 1331, in _find_and_load_unlocked
  File "<frozen importlib._bootstrap>", line 935, in _load_unlocked
  File "<frozen importlib._bootstrap_external>", line 990, in exec_module
  File "<frozen importlib._bootstrap_external>", line 1128, in get_code
  File "<frozen importlib._bootstrap_external>", line 1058, in source_to_code
  File "<frozen importlib._bootstrap>", line 488, in _call_with_frames_removed
  File "/workspaces/CICDLAB2/app/main.py", line 41
    @app.get("/api/health")
SyntaxError: invalid syntax
WARNING:  StatReload detected changes in 'app/main.py'. Reloading...
INFO:     Started server process [30853]
INFO:     Waiting for application startup.
INFO:     Application startup complete.
ERROR:    Traceback (most recent call last):
  File "/usr/local/python/3.12.1/lib/python3.12/asyncio/runners.py", line 194, in run
    return runner.run(main)
           ^^^^^^^^^^^^^^^^
  File "/usr/local/python/3.12.1/lib/python3.12/asyncio/runners.py", line 118, in run
    return self._loop.run_until_complete(task)
           ^^^^^^^^^^^^^^^^^^^^^^^^^^^^^^^^^^^
  File "/usr/local/python/3.12.1/lib/python3.12/asyncio/base_events.py", line 684, in run_until_complete
    return future.result()
           ^^^^^^^^^^^^^^^
  File "/home/codespace/.local/lib/python3.12/site-packages/uvicorn/server.py", line 71, in serve
    await self._serve(sockets)
  File "/home/codespace/.local/lib/python3.12/site-packages/uvicorn/server.py", line 86, in _serve
    await self.startup(sockets=sockets)
  File "/home/codespace/.local/lib/python3.12/site-packages/uvicorn/server.py", line 136, in startup
    server = await loop.create_server(create_protocol, sock=sock, ssl=config.ssl, backlog=config.backlog)
             ^^^^^^^^^^^^^^^^^^^^^^^^^^^^^^^^^^^^^^^^^^^^^^^^^^^^^^^^^^^^^^^^^^^^^^^^^^^^^^^^^^^^^^^^^^^^
  File "/usr/local/python/3.12.1/lib/python3.12/asyncio/base_events.py", line 1581, in create_server
    server._start_serving()
  File "/usr/local/python/3.12.1/lib/python3.12/asyncio/base_events.py", line 315, in _start_serving
    sock.listen(self._backlog)
OSError: [Errno 98] Address already in use

During handling of the above exception, another exception occurred:

Traceback (most recent call last):
  File "/home/codespace/.local/lib/python3.12/site-packages/starlette/routing.py", line 701, in lifespan
    await receive()
  File "/home/codespace/.local/lib/python3.12/site-packages/uvicorn/lifespan/on.py", line 137, in receive
    return await self.receive_queue.get()
           ^^^^^^^^^^^^^^^^^^^^^^^^^^^^^^
  File "/usr/local/python/3.12.1/lib/python3.12/asyncio/queues.py", line 158, in get
    await getter
asyncio.exceptions.CancelledError

Process SpawnProcess-11:
Traceback (most recent call last):
  File "/usr/local/python/3.12.1/lib/python3.12/multiprocessing/process.py", line 314, in _bootstrap
    self.run()
  File "/usr/local/python/3.12.1/lib/python3.12/multiprocessing/process.py", line 108, in run
    self._target(*self._args, **self._kwargs)
  File "/home/codespace/.local/lib/python3.12/site-packages/uvicorn/_subprocess.py", line 80, in subprocess_started
    target(sockets=sockets)
  File "/home/codespace/.local/lib/python3.12/site-packages/uvicorn/server.py", line 67, in run
    return asyncio_run(self.serve(sockets=sockets), loop_factory=self.config.get_loop_factory())
           ^^^^^^^^^^^^^^^^^^^^^^^^^^^^^^^^^^^^^^^^^^^^^^^^^^^^^^^^^^^^^^^^^^^^^^^^^^^^^^^^^^^^^
  File "/usr/local/python/3.12.1/lib/python3.12/asyncio/runners.py", line 194, in run
    return runner.run(main)
           ^^^^^^^^^^^^^^^^
  File "/usr/local/python/3.12.1/lib/python3.12/asyncio/runners.py", line 118, in run
    return self._loop.run_until_complete(task)
           ^^^^^^^^^^^^^^^^^^^^^^^^^^^^^^^^^^^
  File "/usr/local/python/3.12.1/lib/python3.12/asyncio/base_events.py", line 684, in run_until_complete
    return future.result()
           ^^^^^^^^^^^^^^^
  File "/home/codespace/.local/lib/python3.12/site-packages/uvicorn/server.py", line 71, in serve
    await self._serve(sockets)
  File "/home/codespace/.local/lib/python3.12/site-packages/uvicorn/server.py", line 86, in _serve
    await self.startup(sockets=sockets)
  File "/home/codespace/.local/lib/python3.12/site-packages/uvicorn/server.py", line 136, in startup
    server = await loop.create_server(create_protocol, sock=sock, ssl=config.ssl, backlog=config.backlog)
             ^^^^^^^^^^^^^^^^^^^^^^^^^^^^^^^^^^^^^^^^^^^^^^^^^^^^^^^^^^^^^^^^^^^^^^^^^^^^^^^^^^^^^^^^^^^^
  File "/usr/local/python/3.12.1/lib/python3.12/asyncio/base_events.py", line 1581, in create_server
    server._start_serving()
  File "/usr/local/python/3.12.1/lib/python3.12/asyncio/base_events.py", line 315, in _start_serving
    sock.listen(self._backlog)
OSError: [Errno 98] Address already in use
